

Erisoglu:
---------

O2) Not all of the time:

/home/sh18025/project_git/pycluster/initialisations/erisoglu2011.py:112: RuntimeWarning: divide by zero encountered in double_scalars
  return abs(np.std(vector) / np.mean(vector))
/home/sh18025/project_git/pycluster/initialisations/erisoglu2011.py:112: RuntimeWarning: divide by zero encountered in double_scalars
  return abs(np.std(vector) / np.mean(vector))
  
10) Seems to be every time:

  out=out, **kwargs)
/usr/local/lib64/python3.6/site-packages/numpy/core/_methods.py:154: RuntimeWarning: invalid value encountered in true_divide
  ret, rcount, out=ret, casting='unsafe', subok=False)
/usr/local/lib64/python3.6/site-packages/numpy/core/fromnumeric.py:3257: RuntimeWarning: Mean of empty slice.
  out=out, **kwargs)


IKmeans:
--------------------

20)

/usr/local/lib64/python3.6/site-packages/numpy/core/_methods.py:78: RuntimeWarning: invalid value encountered in true_divide
  ret, rcount, out=ret, casting='unsafe', subok=False)
/usr/local/lib64/python3.6/site-packages/numpy/core/fromnumeric.py:2920: RuntimeWarning: Mean of empty slice.
  out=out, **kwargs)
/usr/local/lib64/python3.6/site-packages/numpy/core/_methods.py:78: RuntimeWarning: invalid value encountered in true_divide
  ret, rcount, out=ret, casting='unsafe', subok=False)


Onoda ICA:
----------

05) 

Traceback (most recent call last):
  File "/usr/lib64/python3.6/concurrent/futures/process.py", line 175, in _process_worker
    r = call_item.fn(*call_item.args, **call_item.kwargs)
  File "/usr/lib64/python3.6/concurrent/futures/process.py", line 153, in _process_chunk
    return [fn(*args) for args in chunk]
  File "/usr/lib64/python3.6/concurrent/futures/process.py", line 153, in <listcomp>
    return [fn(*args) for args in chunk]
  File "runner_parallel.py", line 128, in handler
    labels, inertia = run_kmeans(dset, my_init, datadir, ctr_str)
  File "runner_parallel.py", line 69, in run_kmeans
    est.fit(dataset.data)
  File "/usr/local/lib64/python3.6/site-packages/sklearn/cluster/k_means_.py", line 972, in fit
    return_n_iter=True)
  File "/usr/local/lib64/python3.6/site-packages/sklearn/cluster/k_means_.py", line 337, in k_means
    _validate_center_shape(X, n_clusters, init)
  File "/usr/local/lib64/python3.6/site-packages/sklearn/cluster/k_means_.py", line 155, in _validate_center_shape
    % (centers.shape, n_centers))
ValueError: The shape of the initial centers ((2, 2)) does not match the number of clusters 5


Onoda PCA:
----------

05)

"""
Traceback (most recent call last):
  File "/usr/lib64/python3.6/concurrent/futures/process.py", line 175, in _process_worker
    r = call_item.fn(*call_item.args, **call_item.kwargs)
  File "/usr/lib64/python3.6/concurrent/futures/process.py", line 153, in _process_chunk
    return [fn(*args) for args in chunk]
  File "/usr/lib64/python3.6/concurrent/futures/process.py", line 153, in <listcomp>
    return [fn(*args) for args in chunk]
  File "runner_parallel.py", line 128, in handler
    labels, inertia = run_kmeans(dset, my_init, datadir, ctr_str)
  File "runner_parallel.py", line 64, in run_kmeans
    centroids = algorithm.generate(dataset.data, num_clusters)
  File "/home/sh18025/project_git/pycluster/initialisations/onoda2012pca.py", line 25, in generate
    return onoda.find_centers()
  File "/home/sh18025/project_git/pycluster/initialisations/onoda2012.py", line 46, in find_centers
    return self._find_centroids(self._find_components())
  File "/home/sh18025/project_git/pycluster/initialisations/onoda2012pca.py", line 17, in _find_components
    pca.fit(self._data)
  File "/usr/local/lib64/python3.6/site-packages/sklearn/decomposition/pca.py", line 329, in fit
    self._fit(X)
  File "/usr/local/lib64/python3.6/site-packages/sklearn/decomposition/pca.py", line 392, in _fit
    return self._fit_full(X, n_components)
  File "/usr/local/lib64/python3.6/site-packages/sklearn/decomposition/pca.py", line 410, in _fit_full
    % (n_components, n_features))
ValueError: n_components=5 must be between 0 and n_features=2 with svd_solver='full'
"""


Yuan:
-----

02)

"""
Traceback (most recent call last):
  File "/usr/lib64/python3.6/concurrent/futures/process.py", line 175, in _process_worker
    r = call_item.fn(*call_item.args, **call_item.kwargs)
  File "/usr/lib64/python3.6/concurrent/futures/process.py", line 153, in _process_chunk
    return [fn(*args) for args in chunk]
  File "/usr/lib64/python3.6/concurrent/futures/process.py", line 153, in <listcomp>
    return [fn(*args) for args in chunk]
  File "runner_parallel.py", line 128, in handler
    labels, inertia = run_kmeans(dset, my_init, datadir, ctr_str)
  File "runner_parallel.py", line 64, in run_kmeans
    centroids = algorithm.generate(dataset.data, num_clusters)
  File "/home/sh18025/project_git/pycluster/initialisations/yuan2004.py", line 70, in generate
    pointset.append(mydata[next_closest])
IndexError: index 264 is out of bounds for axis 0 with size 264
"""

